Workbook

Sheet Instrucciones
A1: LunfaBench · Planilla del conjunto curado
A3: Son los 90 términos del conjunto curado: 40 falsos amigos, 20 sin homónimo, 15 polisémicos y 15 controles, mezclados. Cada uno trae dos fragmentos reales (A y B) de canciones de artistas de Buenos Aires.
A4: Qué hace cada anotador
A5: 1. Escribí tu nombre en «anotador». Cada fila la anotan dos personas, por separado: no mires la columna de la otra persona hasta terminar.
A6: 2. En «capa», elegí de la lista qué tipo de palabra es, pensando en Buenos Aires:
A7: falso_amigo: tiene una acepción de España o México que acá no se usa (curro: acá negocio turbio, en España trabajo).
A8: polisemico_interno: tiene varias acepciones y todas se usan acá (pileta: piscina y pileta de la cocina).
A9: lunfardo_sin_homonimo: no existe con otro sentido en España ni en México (bondi, chamuyo).
A10: espanol_general: es una palabra común del español, que significa lo mismo en todos lados (ventana).
A11: 3. En «fragmento», elegí A o B: el que usa la acepción de referencia. Si los dos la usan, el que mejor se entienda. Si ninguno, el más cercano, y contalo en «comentario».
A12: 4. Si elegiste falso_amigo, escribí la acepción competidora y dónde se usa, por ejemplo «trabajo (España)».
A13: Se puede consultar el DLE y el Diccionario de americanismos. No consultes Wiktionary ni Wikcionario: son la fuente del filtro automático y el acuerdo quedaría inflado.
... A18: Ejemplo de fila completa (el término no está en la planilla)
A20: término | B20: acepción de referencia | C20: anotador 1 | D20: capa 1 | E20: fragmento 1 | F20: acepción competidora 1
A21: torta | C21: Tomás | D21: falso_amigo | E21: A | F21: (la acepción de España o México)

Sheet Anotación
A1: id | B1: término | C1: acepción de referencia | D1: fuente | E1: fragmento A | F1: canción A | G1: fragmento B | H1: canción B | I1: anotador 1 | J1: capa 1 | K1: fragmento 1 | L1: acepción competidora 1 | M1: anotador 2 | N1: capa 2 | O1: fragmento 2 | P1: acepción competidora 2 | Q1: coincide capa | R1: coincide fragmento | S1: capa final | T1: fragmento final | U1: comentario
A2: CUR-001 | B2: gira | C2: Ir a muchos lugares en un mismo día Habitualmente se lo usa cuando salen a varias fiestas una misma noche | D2: diccionarioargentino.com | E2: quiero a todos los pibe' cantina / Y que levanten bien la mano los que se bancan la gira / No tomo Chandon, me sirve el Federico | F2: Tamo Chelo · El Noba (2021) | G2: Maniac in my mind en medio de la ciudad / Girl, gira el volante del todo / Boxea sin guantes que es lo que quieren todos | H2: KAMIKAZE · Sofía Gabanna (2023) | I2: Tomas Borda | J2: polisemico_interno | K2: A | M2: Valentín Garfi | N2: lunfardo_sin_homonimo | O2: A | Q2: =IF(OR(J2="",N2=""),"",IF(J2=N2,"sí","no")) | R2: =IF(OR(K2="",O2=""),"",IF(K2=O2,"sí","no"))
A3: CUR-002 | B3: idear | C3: Concebir algo nuevo con la imaginación. | D3: Wikcionario | E3: Sabiendo que no quiero que te quedes / El hacedor de ideas se estrella en su carrera / La dirección del tiempo es frágil y se tienta | F3: Pinamar · Francisco Bochatón | G3: Al anochecer seducido de tensión / Vuela sin control ideando la misión / Vértigo inmoral, juicio sin identidad | H3: Adicto · D-mente | I3: Tomas Borda | J3: espanol_general | K3: B | M3: Valentín Garfi | N3: espanol_general | O3: B | Q3: =IF(OR(J3="",N3=""),"",IF(J3=N3,"sí","no")) | R3: =IF(OR(K3="",O3=""),"",IF(K3=O3,"sí","no"))
A4: CUR-003 | B4: chamuyo | C4: Hablarle a una persona con un propósito, mintiéndole para que te crea. | D4: diccionarioargentino.com | E4: Tango de triste motivo / Cuando siento tu chamuyo / Se queda en mi alma el arrullo | F4: Apología del Tango · Tita Merello (1969) | I4: Tomas Borda | J4: lunfardo_sin_homonimo | K4: A | M4: Valentín Garfi | N4: lunfardo_sin_homonimo | O4: A | Q4: =IF(OR(J4="",N4=""),"",IF(J4=N4,"sí","no")) | R4: =IF(OR(K4="",O4=""),"",IF(K4=O4,"sí","no"))
A5: CUR-004 | B5: cerrar | C5: Colocar o modificar algo para evitar su apertura. | D5: Wikcionario | E5: Puedo relajar otra vez / Y bailar cuando cierro los ojos / Pensando en vos | F5: Puedo Sentirlo · David Lebón (1986) | G5: Solo la muerte esconde el ultimo latido debil de mi corazón / Cuando cerre mis manos / Me guarde estos recuerdos | H5: Reescribir Tragedias Sobre Libros Y Llamas · Dar Sangre (2008) | I5: Tomas Borda | J5: espanol_general | K5: B | M5: Valentín Garfi | N5: espanol_general | O5: B | Q5: =IF(OR(J5="",N5=""),"",IF(J5=N5,"sí","no")) | R5: =IF(OR(K5="",O5=""),"",IF(K5=O5,"sí","no"))
A6: CUR-005 | B6: botón | C6: Soplón, delator | D6: diccionarioargentino.com | E6: Que si en la calle me afila / Me pongo al lao del botón / ¡Lo que más bronca me da | F6: Chorra · Edmundo Rivero (1959) | G6: Y el fueye, es un bandoneón / El vigilante, un botón / La policía, la cana | H6: Milonga Lunfarda · Edmundo Rivero (1972) | I6: Tomas Borda | J6: falso_amigo | K6: B | L6: Pieza pequeña de metal, hueso, nácar u otra materia, forrada de tela o sin forrar, que se pone en los vestidos para que, entrando en el ojal, los abroche y asegure. También se pone por adorno. | M6: Valentín Garfi | N6: falso_amigo | O6: B | P6: Elevación redondeada y plana de la piel, grano/verruga (Esp.) | Q6: =IF(OR(J6="",N6=""),"",IF(J6=N6,"sí","no")) | R6: =IF(OR(K6="",O6=""),"",IF(K6=O6,"sí","no"))
A7: CUR-006 | B7: burra | C7: Forma villera de denominar la cola de una dama. | D7: diccionarioargentino.com | E7: Las pibita' me llaman, 'tamo' chelo / Me etiquetó en su burra, 'tamo' chelo / Ese gato hatea, 'tamo' chelo | F7: Tamo Chelo · El Noba (2021) | G7: ¿Y ahora qué vamo' a hacer? / La baby lo mueve, qué burra, no sabés / Tiene flow, no hay compe (No hay compe) | H7: Del Año · El Noba (2021) | I7: Tomas Borda | J7: polisemico_interno | K7: A | M7: Valentín Garfi | N7: polisemico_interno | O7: A | Q7: =IF(OR(J7="",N7=""),"",IF(J7=N7,"sí","no")) | R7: =IF(OR(K7="",O7=""),"",IF(K7=O7,"sí","no"))
A8: CUR-007 | B8: gritar | C8: Hablar con la voz muy fuerte, para intimidar, alertar o comunicarse cuando el ruido de fondo impide la conversación normal. | D8: Wikcionario | E8: quieren montar como una puta encima de mi disco / Me gustaba escucharte gritar, bajaba to' el volumen / Bebiendo buena champaña y OG Kush pa' que | F8: Oye Baby · Zaramay (2020) | G8: Los que al mirar no se hacen / Ciegos por gritar / Sin pretender sen premiados | H8: Rugen Sus Voces · D-mente | I8: Tomas Borda | J8: espanol_general | K8: B | M8: Valentín Garfi | N8: espanol_general | O8: B | Q8: =IF(OR(J8="",N8=""),"",IF(J8=N8,"sí","no")) | R8: =IF(OR(K8="",O8=""),"",IF(K8=O8,"sí","no"))
A9: CUR-008 | B9: morocho | C9: Persona de tez morena y/o de cabello negro o castaño oscuro. | D9: diccionarioargentino.com | E9: Duki dispara aunque Mauro dude (Dude) / Soy el niño 'el año, morocho achinado / Llevo el doble caño, flow polarizado | F9: Hello Cotto · Duki (2017) | G9: ¿Dónde estarán Traverso, el Cordobés y el Noy / El Pardo Augusto, Flores y el Morocho Aldao? / Así empezó mi vuelo de zorzal | H9: El Cantor de Buenos Aires · Roberto Goyeneche | I9: Tomas Borda | J9: polisemico_interno | K9: A | M9: Valentín Garfi | N9: polisemico_interno | O9: A | Q9: =IF(OR(J9="",N9=""),"",IF(J9=N9,"sí","no")) | R9: =IF(OR(K9="",O9=""),"",IF(K9=O9,"sí","no"))
A10: CUR-009 | B10: timba | C10: Casa de juegos de azar o directamente jugar juegos de cartas | D10: diccionarioargentino.com | E10: Su boca de fuego, otra vez, quiero besar / Basta de carreras, se acabó la timba / Un final reñido yo no vuelvo a ver | F10: Por Una Cabeza · Carlos Gardel (1935) | G10: De sabihondos y suicidas / Yo aprendí filosofía, dados, timba... / Y la poesía cruel | H10: Cafetín de Buenos Aires · Edmundo Rivero (1959) | I10: Tomas Borda | J10: falso_amigo | K10: A | L10: casa de juego. | M10: Valentín Garfi | N10: falso_amigo | O10: A | P10: Panza o barriga (Méx., CR, El Salv., Guat., Hond., Nic.) | Q10: =IF(OR(J10="",N10=""),"",IF(J10=N10,"sí","no")) | R10: =IF(OR(K10="",O10=""),"",IF(K10=O10,"sí","no"))
A11: CUR-010 | B11: manija | C11: Tener manija es tener ansias o entusiasmo por algo. | D11: diccionarioargentino.com | E11: Con par de champetas yo siempre corono / 'Tamo re manija y nunca paramo' / Si pinta el after ahí nos mandamo' | F11: ALLA · EL NOBA (2022) | G11: En una cancha o en un bar / Dando la vuelta manija me doy / Subiendo al latido de esta vibración | H11: Toco y me voy · Bersuit Vergarabat (2000) | I11: Tomas Borda | J11: polisemico_interno | K11: A | M11: Valentín Garfi | N11: polisemico_interno | O11: A | Q11: =IF(OR(J11="",N11=""),"",IF(J11=N11,"sí","no")) | R11: =IF(OR(K11="",O11=""),"",IF(K11=O11,"sí","no"))
A12: CUR-011 | B12: viejo | C12: Sinonimo de padre/papá en el lunfardo argentino. | D12: diccionarioargentino.com | E12: por sonsa, a fuerza de compasión / Como quedaste en la vía y tu viejo, un pobre tano / Era chivo con los cosos pelandrunes como vos | F12: Lloró Como Una Mujer · Edmundo Rivero (1967) | G12: Mi mamá tomando merca, todo enfrente 'e mi cara (Fiumba) / Y mi viejo después de eso me echó fuera 'e la casa / Pero si no | H12: OPA · Dillom (2021) | I12: Tomas Borda | J12: falso_amigo | K12: A | L12: Se dice de la persona de edad | M12: Valentín Garfi | N12: falso_amigo | O12: A | P12: Mujer, persona del sexo femenino (coloq.; Bol. y Méx.) | Q12: =IF(OR(J12="",N12=""),"",IF(J12=N12,"sí","no")) | R12: =IF(OR(K12="",O12=""),"",IF(K12=O12,"sí","no"))
A13: CUR-012 | B13: macana | C13: Error, equivocación; cosa mal hecha. | D13: diccionarioargentino.com | E13: De envenenarse mi hermana / No hay bochinche ni macana / Que en tu homenaje no hiciera | F13: Apología del Tango · Tita Merello (1969) | G13: Rebota en la fuente / ¡Ay, qué macana! / Se posa en su frente | H13: La tortuga Uga · Flor Ansaldo (2020) | I13: Tomas Borda | J13: falso_amigo | K13: B | L13: f. Am. Garrote grueso. Hay vigilantes de barrio (muchachos adolescentes con macanas y tubos de fierro). [C]. | M13: Valentín Garfi | N13: polisemico_interno | O13: B | Q13: =IF(OR(J13="",N13=""),"",IF(J13=N13,"sí","no")) | R13: =IF(OR(K13="",O13=""),"",IF(K13=O13,"sí","no"))
A14: CUR-013 | B14: pico | C14: En Argentina, dícese que significa o representa, la accion humana de indole apareamental entre humanos, comunmente denominada "beso". | D14: diccionarioargentino.com | E14: Todo' los pibito' fumando del rico / Toda' esa' bandida' quieren darme un pico / Por allá el machimbre parece milico | F14: Tamo Chelo · El Noba (2021) | G14: Un bicho gordo como un salchichón / Dice “qué rico” y abriendo el pico / Pesca al perrito como un camarón | H14: El Show Del Perro Salchicha · María Elena Walsh (1966) | I14: Tomas Borda | J14: falso_amigo | K14: A | L14: Cima puntiaguda de una montaña | M14: Valentín Garfi | N14: falso_amigo | O14: A | P14: Colín de pan pequeño (Esp.) | Q14: =IF(OR(J14="",N14=""),"",IF(J14=N14,"sí","no")) | R14: =IF(OR(K14="",O14=""),"",IF(K14=O14,"sí","no"))
A15: CUR-014 | B15: cana | C15: Refiriéndose a la policia, a ir detenido a la comisaria o prisión. | D15: diccionarioargentino.com | E15: Que se nos cruza en la vida / Por vos he morfao más canas / Que pelos tengo en el mate | F15: Apología del Tango · Tita Merello (1969) | G15: Como me engrupiste vos / Está en cana, prontuariado / Como agente 'e la camorra | H15: Chorra · Edmundo Rivero (1959) | I15: Tomas Borda | J15: polisemico_interno | K15: B | M15: Valentín Garfi | N15: polisemico_interno | O15: B | Q15: =IF(OR(J15="",N15=""),"",IF(J15=N15,"sí","no")) | R15: =IF(OR(K15="",O15=""),"",IF(K15=O15,"sí","no")) | U15: Fragmento A usa el sentido literal (pelo canoso: "...más canas que pelos tengo en el mate"), no el rioplatense (policía/preso); por eso se eligió B.
A16: CUR-015 | B16: mango | C16: Sinónimo de dinero. | D16: diccionarioargentino.com | E16: De manguero doctorao / Y que un mango descubrís / Aunque lo hayan enterrao | F16: Dónde Hay Un Mango? · Tita Merello (1965) | G16: Cuando rajés los tamangos / Buscando este mango / Que te haga morfar | H16: Yira, Yira · Carlos Gardel (1930) | I16: Tomas Borda | J16: falso_amigo | K16: B | L16: Parte alargada, estrecha y con un extremo libre, por la que se puede agarrar un instrumento o utensilio | M16: Valentín Garfi | N16: falso_amigo | O16: B | P16: Persona guapa, atractiva (El Salv., Méx. y Nic.) | Q16: =IF(OR(J16="",N16=""),"",IF(J16=N16,"sí","no")) | R16: =IF(OR(K16="",O16=""),"",IF(K16=O16,"sí","no"))
A17: CUR-016 | B17: malevo | C17: Vulgar, propio del arrabal. | D17: Wikcionario | E17: Se dice de mí / Se dice que soy fiera, que camino a lo malevo / Que soy chueca y que me muevo con un aire compadrón | F17: Se Dice de Mí · Tita Merello (1955) | G17: Nacido en los suburbios / Malevos y turbios / Hoy | H17: Yo soy el tango · Miguel Caló | I17: Tomas Borda | J17: lunfardo_sin_homonimo | K17: A | M17: Valentín Garfi | N17: lunfardo_sin_homonimo | O17: A | Q17: =IF(OR(J17="",N17=""),"",IF(J17=N17,"sí","no")) | R17: =IF(OR(K17="",O17=""),"",IF(K17=O17,"sí","no"))
A18: CUR-017 | B18: gil | C18: Insulto a una persona que no cumple lo pautado o no tiene códigos | D18: diccionarioargentino.com | E18: En el amor yo solo sé / Que a más de un gil dejé de a pie / Podrán decir, podrán hablar | F18: Se Dice de Mí · Tita Merello (1955) | G18: ¡Lo que más bronca me da / Es haber estao' tan gil! / Si hace un mes me desayuno | H18: Chorra · Edmundo Rivero (1959) | I18: Tomas Borda | J18: lunfardo_sin_homonimo | K18: A | M18: Valentín Garfi | N18: lunfardo_sin_homonimo | O18: A | Q18: =IF(OR(J18="",N18=""),"",IF(J18=N18,"sí","no")) | R18: =IF(OR(K18="",O18=""),"",IF(K18=O18,"sí","no"))
A19: CUR-018 | B19: bailar | C19: Derrotar contundentemente. | D19: Wikcionario | E19: de aquí, cuántos de ellos aún están / Ahora mírame a mí, que te la puedo bailar / Solo elígeme el beat, el resto lo hace papá | F19: Vivimos Deprisa · Sofía Gabanna (2021) | I19: Tomas Borda | J19: polisemico_interno | K19: A | M19: Valentín Garfi | N19: polisemico_interno | O19: A | Q19: =IF(OR(J19="",N19=""),"",IF(J19=N19,"sí","no")) | R19: =IF(OR(K19="",O19=""),"",IF(K19=O19,"sí","no"))
A20: CUR-019 | B20: pobre | C20: Que tiene pocos bienes materiales. | D20: Wikcionario | E20: ahí que tenerla presente / Muchas te amarán siendo rico y pocas siendo pobre, fuck (Ey) / Si lo que yo hago yo no lo pueden hacer | F20: Nena · Zaramay (2018) | G20: Se van al sobre, yo no sobro (No sobro) / De pobre a rico como Rondo (Rondo) / Ya me conocen como el monstruo | H20: Hello Cotto · Duki (2017) | I20: Tomas Borda | J20: espanol_general | K20: A | M20: Valentín Garfi | N20: espanol_general | O20: A | Q20: =IF(OR(J20="",N20=""),"",IF(J20=N20,"sí","no")) | R20: =IF(OR(K20="",O20=""),"",IF(K20=O20,"sí","no"))
A21: CUR-020 | B21: cotorro | C21: Inmueble o habitación destinada para encuentros amorosos clandestinos. | D21: Wikcionario | E21: Agarrar lo que está hecho / El cotorro es el lugar / Donde se hace el amor | F21: Milonga Lunfarda · Edmundo Rivero (1972) | G21: Pa' olvidarme de tu amor / Cuando voy a mi cotorro / Y lo veo desarreglado | H21: Mi noche triste · Carlos Gardel (1917) | I21: Tomas Borda | J21: falso_amigo | K21: A | L21: adj. Méx. Dicho de una cosa: Bonita, atractiva, interesante. | M21: Valentín Garfi | N21: falso_amigo | O21: A | P21: Bonita, atractiva, interesante (adj., Méx.) | Q21: =IF(OR(J21="",N21=""),"",IF(J21=N21,"sí","no")) | R21: =IF(OR(K21="",O21=""),"",IF(K21=O21,"sí","no"))
A22: CUR-021 | B22: piola | C22: Adjetivo que califica a quien resuelve situaciones gracias a su ingenio; también algo que está bueno. | D22: diccionarioargentino.com | E22: Acá no se usa chupín, se viste ancho / No te hagas el piola, si en Varela sos un pancho / Si quiero te arrebato, no compro | F22: PICA · EL NOBA (2022) | G22: Estoy de gira por el barrio y mañana tengo fecha / Pero me porto piola, así la 12 no sospecha / (Fuck, try me) | H22: A$AP · Dillom (2019) | I22: Tomas Borda | J22: falso_amigo | K22: A | L22: f. Cuerda delgada. | M22: Valentín Garfi | N22: polisemico_interno | O22: A | Q22: =IF(OR(J22="",N22=""),"",IF(J22=N22,"sí","no")) | R22: =IF(OR(K22="",O22=""),"",IF(K22=O22,"sí","no"))
A23: CUR-022 | B23: curro | C23: Situación arreglada previamente, generalmente de manera injusta y/o inmoral. | D23: diccionarioargentino.com | E23: dealer' en lo' burro' (Uh) / Aprovechen el momento y saquen provecho al curro (Uh, uh-uh) / Ya tú sabe', canto envido (Ya lo dije con susurro) | F23: Freestyle Session #14 “LOS INTOCABLES” · Zaramay (2021) | G23: Sos cadenera, flor sin berretines / Que currás a los cuores con tu rango; / Pero el choma que aceita tus patines | H23: A Buenos Aires Lunfa · Edmundo Rivero (1967) | I23: Tomas Borda | J23: falso_amigo | K23: A | L23: m. coloq. trabajo (‖ acción de trabajar). | M23: Valentín Garfi | N23: falso_amigo | O23: A | P23: Trabajo o labor (uso cotidiano en España; el DLE no lo marca regionalmente) | Q23: =IF(OR(J23="",N23=""),"",IF(J23=N23,"sí","no")) | R23: =IF(OR(K23="",O23=""),"",IF(K23=O23,"sí","no"))
A24: CUR-023 | B24: pendejo | C24: 1 Usado para describir a alguien joven (Pendejo significa realmente pelo del pubis) 2 Usado a veces para describir a persona despectivamente a alguien medio tonto. | D24: diccionarioargentino.com | E24: El día que muera, moriré en mi ley, ah / Una pendeja egoísta, un poco masoquista / Su familia es cheta, sus papás son macristas | F24: Buenos tiempos · Dillom (2024) | G24: Me jode / Lejos del complejo de pendejos que la soben / Ven un lazo con el viejo rap, entonces no lo roben | H24: Oro Puro · 808god (2020) | I24: Tomas Borda | J24: falso_amigo | K24: A | L24: adj. coloq. Tonto, estúpido. Mex | M24: Valentín Garfi | N24: falso_amigo | O24: A | P24: Tonto, estúpido (muy asociado a México; el DLE no lo marca regionalmente) | Q24: =IF(OR(J24="",N24=""),"",IF(J24=N24,"sí","no")) | R24: =IF(OR(K24="",O24=""),"",IF(K24=O24,"sí","no"))
A25: CUR-024 | B25: guita | C25: Significa dinero, plata. | D25: diccionarioargentino.com | E25: Y al vivo le baten rana / La guita o el vento es / El dinero que circula | F25: Milonga Lunfarda · Edmundo Rivero (1972) | G25: fin de mes me dan miguitas para que no me queje / Puta, yo quiero mi guita, no escuchar boludeces / Estoy tan cansado de este sentimiento | H25: Mi peor enemigo · Dillom (2024) | I25: Tomas Borda | J25: lunfardo_sin_homonimo | K25: B | M25: Valentín Garfi | N25: lunfardo_sin_homonimo | O25: B | Q25: =IF(OR(J25="",N25=""),"",IF(J25=N25,"sí","no")) | R25: =IF(OR(K25="",O25=""),"",IF(K25=O25,"sí","no"))
A26: CUR-025 | B26: chabón | C26: Término coloquial para referirse a un chico o una chica. | D26: diccionarioargentino.com | E26: El chorro, un vulgar ladrón / Al zonzo, llaman chabón / Y al vivo le baten rana | F26: Milonga Lunfarda · Edmundo Rivero (1972) | G26: Ese cuerpo compadrón, algún... / Algún oscuro chabón / Será el llamado a cargarte | H26: En un feca · Edmundo Rivero (1975) | I26: Tomas Borda | J26: lunfardo_sin_homonimo | K26: A | M26: Valentín Garfi | N26: lunfardo_sin_homonimo | O26: A | Q26: =IF(OR(J26="",N26=""),"",IF(J26=N26,"sí","no")) | R26: =IF(OR(K26="",O26=""),"",IF(K26=O26,"sí","no"))
A27: CUR-026 | B27: viste | C27: Muletilla para confirmar que el interlocutor sigue el relato; equivale a «¿sabés?» o «¿entendés?». | D27: definición del grupo (no figura en Wikcionario ni en diccionarioargentino.com) | E27: Las tardecitas de Buenos Aires tiene ese qué sé yo, ¿viste? / Salís de tu casa por Arenales, lo de siempre en la calle y en | F27: Balada Para un Loco · Roberto Goyeneche (1969) | I27: Tomas Borda | J27: polisemico_interno | K27: A | M27: Valentín Garfi | N27: polisemico_interno | O27: A | Q27: =IF(OR(J27="",N27=""),"",IF(J27=N27,"sí","no")) | R27: =IF(OR(K27="",O27=""),"",IF(K27=O27,"sí","no")) | U27: Acepción rioplatense = muletilla confirmatoria; "viste" como forma verbal de "ver" es general en todo el español.
A28: CUR-027 | B28: flor | C28: Antepuesto a un sustantivo, indica que es grande o notable: flor de susto, flor de quilombo. | D28: definición del grupo (el sentido intensificador no figura en las tres fuentes del pipeline) | E28: te da también te quita / Que se hace la viva y está muerta la mosquita / Que parecía un duro y es un flor de mantequita | F28: Esa mierda · Sara Hebe (2012) | G28: La luz de todos los colores, cantando / El color de una piel y de una flor / Una guitarra y tu voz | H28: Estaré · Los Visitantes (1996) | I28: Tomas Borda | J28: polisemico_interno | K28: A | M28: Valentín Garfi | N28: polisemico_interno | O28: A | Q28: =IF(OR(J28="",N28=""),"",IF(J28=N28,"sí","no")) | R28: =IF(OR(K28="",O28=""),"",IF(K28=O28,"sí","no"))
A29: CUR-028 | B29: quilombo | C29: Forma de decir caos, desorden, pelea, un gran problema. | D29: diccionarioargentino.com | E29: que pega como Cotto / Soy de lo' pibes del fondo (Uh), de los adicto' al quilombo (Uh) / Mejor no ronquen con mi combo (Más na') | F29: Hello Cotto · Duki (2017) | G29: Estamos todos jugados, nada nos importa ya / Sigamos haciendo quilombo / La yuta no nos va llevar | H29: Los Pibes Chorros · Los Pibes Chorros (2001) | I29: Tomas Borda | J29: lunfardo_sin_homonimo | K29: A | M29: Valentín Garfi | N29: lunfardo_sin_homonimo | O29: A | Q29: =IF(OR(J29="",N29=""),"",IF(J29=N29,"sí","no")) | R29: =IF(OR(K29="",O29=""),"",IF(K29=O29,"sí","no"))
A30: CUR-029 | B30: jalar | C30: Inhalar con fines psicoactivos los vapores de un disolvente, generalmente colocándolo en una bolsa que se acerca a la boca y la nariz. | D30: Wikcionario | E30: Podés encontrarme por ahí, perdido sin Waze / Jalando popper con los gays / El día que muera, moriré en mi ley | F30: Buenos tiempos · Dillom (2024) | G30: Te busco x esos pasillos / Por ti jalo el gatillo / Que lo que tenga q pasar | H30: Quiero · Stefy Xipolitakis | I30: Tomas Borda | J30: falso_amigo | K30: A | L30: tr. coloq. Tirar de algo o de alguien. Esp | M30: Valentín Garfi | N30: polisemico_interno | O30: A | Q30: =IF(OR(J30="",N30=""),"",IF(J30=N30,"sí","no")) | R30: =IF(OR(K30="",O30=""),"",IF(K30=O30,"sí","no"))
A31: CUR-030 | B31: tesoro | C31: Depósito de plata, oro, y otros bienes de gran valor. | D31: Wikcionario | E31: Vamos a desembarcar / Muchos tesoros, joyas y perlas / Que ha conseguido ganar | F31: El Pirata Cara de Rata · Flor Ansaldo (2020) | G31: De tus ojos nunca quiero verme lejos / ¡Divinos tesoros de amor y de ensueño! / De tus ojos vivo | H31: Ruego · Felipe Boero | I31: Tomas Borda | J31: espanol_general | K31: B | M31: Valentín Garfi | N31: espanol_general | O31: B | Q31: =IF(OR(J31="",N31=""),"",IF(J31=N31,"sí","no")) | R31: =IF(OR(K31="",O31=""),"",IF(K31=O31,"sí","no"))
A32: CUR-031 | B32: capo | C32: Ser capo es ser muy bueno en algo, ser el mejor. | D32: diccionarioargentino.com | E32: quedo guapo si la ven conmigo, eh / Guapo eh, guapo, uh, sapo, soy el capo del hood / Tanto al mes, tanto flu', guapo, guapo, guapo | F32: Guapo · YSY A (2018) | G32: ¡Con sentimiento! / El Ruca, el Loco Ale y Toca, el capo de la villa / Re tirado y descontrolado, un pucho loco me estoy fumando | H32: Pucho Loco · Damas Gratis (2008) | I32: Tomas Borda | J32: polisemico_interno | K32: B | M32: Valentín Garfi | N32: polisemico_interno | O32: B | Q32: =IF(OR(J32="",N32=""),"",IF(J32=N32,"sí","no")) | R32: =IF(OR(K32="",O32=""),"",IF(K32=O32,"sí","no"))
A33: CUR-032 | B33: muerto | C33: Inhábil, sobre todo cuando refiere a juegos o deportes. | D33: Wikcionario | E33: nunca me quiso, y estoy loco por su beso / Mañana puedo estar muerto, como también estar preso / Si salgo de casa, no sabré si vo'a | F33: Freestyle Session #5 · Zaramay (2019) | G33: Ver fuerza salir del lodo / Watch me, ya muerta, pero escribiendo hits / I am confuse como Cuasimodo | H33: KAMIKAZE · Sofía Gabanna (2023) | I33: Tomas Borda | J33: polisemico_interno | K33: B | M33: Valentín Garfi | N33: polisemico_interno | O33: B | Q33: =IF(OR(J33="",N33=""),"",IF(J33=N33,"sí","no")) | R33: =IF(OR(K33="",O33=""),"",IF(K33=O33,"sí","no")) | U33: Ni A ni B reflejan claramente el sentido rioplatense de referencia (inhábil en juegos/deportes); ambos suenan al sentido literal. Revisar con Tomás.
A34: CUR-033 | B34: birra | C34: Forma de decirle a la cerveza. | D34: diccionarioargentino.com | E34: Acá siempre son 4:20, y estamo' de la cabeza, con simpleza / Birra barata y mala en lata, má' la planta santa esa / La que calma | F34: CANGURO · WOS (2019) | G34: se hace larga tengo que remar / Si es un día de calor unas birras tomar / Pero hay algo que me atrapa y no puedo escapar | H34: Lo Peor · Kumbia Queers (2015) | I34: Tomas Borda | J34: lunfardo_sin_homonimo | K34: A | M34: Valentín Garfi | N34: lunfardo_sin_homonimo | O34: A | Q34: =IF(OR(J34="",N34=""),"",IF(J34=N34,"sí","no")) | R34: =IF(OR(K34="",O34=""),"",IF(K34=O34,"sí","no"))
A35: CUR-034 | B35: vento | C35: Dinero, en especial en efectivo. | D35: Wikcionario | E35: Y al vivo le baten rana / La guita o el vento es / El dinero que circula | F35: Milonga Lunfarda · Edmundo Rivero (1972) | G35: 'Tam-tam-tamo' chelo / Mis ñeri' toman tussi en un Vento / De como terminamo', mejor no te cuento | H35: Tamo Chelo · El Noba (2021) | I35: Tomas Borda | J35: lunfardo_sin_homonimo | K35: A | M35: Valentín Garfi | N35: lunfardo_sin_homonimo | O35: A | Q35: =IF(OR(J35="",N35=""),"",IF(J35=N35,"sí","no")) | R35: =IF(OR(K35="",O35=""),"",IF(K35=O35,"sí","no"))
A36: CUR-035 | B36: fierro | C36: Arma de fuego. | D36: diccionarioargentino.com | E36: de usar tanga (Jaja) / Pa' pelea' el Luna Park, desde que hay fierro nadie e' langa / No pode' hablar de má' cuando hay dos ase' | F36: Freestyle Session #14 “LOS INTOCABLES” · Zaramay (2021) | G36: La mafia a tu banda la saca del vuelo / Y listo, llevo fierro cheto y chico / Porque .9 usan los milico' (Oh) | H36: Tamo Chelo (Remix) · EL NOBA (2022) | I36: Tomas Borda | J36: polisemico_interno | K36: A | M36: Valentín Garfi | N36: polisemico_interno | O36: A | Q36: =IF(OR(J36="",N36=""),"",IF(J36=N36,"sí","no")) | R36: =IF(OR(K36="",O36=""),"",IF(K36=O36,"sí","no"))
A37: CUR-036 | B37: turro | C37: Persona de mal proceder, de poca confianza. | D37: diccionarioargentino.com | E37: son más de lo mismo (Oh, oh) / Y que vos querés un turro que esté puesto pa' quererte / Y pa' sacarte de tu vida normal | F37: Mamichula · Trueno (2020) | G37: Pa' eso feka' tengo repelente / Yo no soy un turro, tengo el corazón valiente, yah / Yo soy del barrio desde que nací | H37: Azul y Oro · Trueno (2020) | I37: Tomas Borda | J37: lunfardo_sin_homonimo | K37: A | M37: Valentín Garfi | N37: lunfardo_sin_homonimo | O37: A | Q37: =IF(OR(J37="",N37=""),"",IF(J37=N37,"sí","no")) | R37: =IF(OR(K37="",O37=""),"",IF(K37=O37,"sí","no"))
A38: CUR-037 | B38: dormir | C38: Engañar a alguien para obtener un beneficio. | D38: Wikcionario | E38: Cuando pierda todas las partidas / Cuando duerma con la soledad / Cuando se me cierren las salidas | F38: Resistiré (Versión Reggaetón) · Zulma Lobato (2009) | G38: Turbulencia, aguamiel / El día se durmió / Aplazado al calor, pasionaria | H38: Alas de la Mañana · Lito Epumer (2004) | I38: Tomas Borda | J38: polisemico_interno | K38: A | M38: Valentín Garfi | N38: polisemico_interno | O38: A | Q38: =IF(OR(J38="",N38=""),"",IF(J38=N38,"sí","no")) | R38: =IF(OR(K38="",O38=""),"",IF(K38=O38,"sí","no")) | U38: Ni A ni B reflejan claramente el sentido rioplatense de referencia (engañar); ambos suenan al sentido literal. Revisar con Tomás.
A39: CUR-038 | B39: taco | C39: Parte posterior elevada del calzado. | D39: Wikcionario | E39: elegante hablando, lady, no hace falta un saco / Y a ti pa' ser mujer no te hacen falta tacos / Mis negro' experimentan con el amoniaco | F39: Nena · Zaramay (2018) | G39: Salta, bitch, jumpin' and jumpin' (Jumpin'), jumpin' / Bitch, now, la quiero en tacos, compitiendo como Elvira Hancock (Uh) / Que tengo mis puta' pero quiero a | H39: Elvira · 808God (2016) | I39: Tomas Borda | J39: falso_amigo | K39: A | L39: Tortilla de maíz enrollada con relleno, comida típica (Méx.) | M39: Valentín Garfi | N39: falso_amigo | O39: A | P39: Tortilla de maíz enrollada con relleno, comida típica (Méx.) | Q39: =IF(OR(J39="",N39=""),"",IF(J39=N39,"sí","no")) | R39: =IF(OR(K39="",O39=""),"",IF(K39=O39,"sí","no"))
A40: CUR-039 | B40: boludo | C40: Persona estupida, tonta, una persona imbecil | D40: diccionarioargentino.com | E40: a llevarte a lo profundo de mi mente / ¿Te pensás que soy boludo? ¿Que no sé cuándo me mienten? / Te pensás que yo no tengo | F40: Muñecas · Dillom (2024) | G40: Me la pone tan gorda que le hacen body-shaming / (Ay, same, boluda, yo también tengo ascendente en sagitario, | H40: Buenos tiempos · Dillom (2024) | I40: Tomas Borda | J40: falso_amigo | K40: B | L40: adj. Méx. Que tiene protuberancias. | M40: Valentín Garfi | N40: falso_amigo | O40: B | P40: Que tiene bultos o protuberancias (Méx.) | Q40: =IF(OR(J40="",N40=""),"",IF(J40=N40,"sí","no")) | R40: =IF(OR(K40="",O40=""),"",IF(K40=O40,"sí","no"))
...

Sheet Resumen
A1: Avance
A2: Términos | B2: =COUNTIF('Anotación'!$A$2:$A$91,"?*")
A3: Con anotador 1 | B3: =COUNTIF('Anotación'!$J$2:$J$91,"?*")
A4: Con anotador 2 | B4: =COUNTIF('Anotación'!$N$2:$N$91,"?*")
A5: Con capa final | B5: =COUNTIF('Anotación'!$S$2:$S$91,"?*")
A6: Acuerdo en capa | B6: =IFERROR(COUNTIF('Anotación'!$Q$2:$Q$91,"sí")/(COUNTIF('Anotación'!$Q$2:$Q$91,"sí")+COUNTIF('Anotación'!$Q$2:$Q$91,"no")),"")
A7: Acuerdo en fragmento | B7: =IFERROR(COUNTIF('Anotación'!$R$2:$R$91,"sí")/(COUNTIF('Anotación'!$R$2:$R$91,"sí")+COUNTIF('Anotación'!$R$2:$R$91,"no")),"")
A9: Capa final | B9: Términos
A10: falso_amigo | B10: =COUNTIF('Anotación'!$S$2:$S$91,"falso_amigo")
A11: polisemico_interno | B11: =COUNTIF('Anotación'!$S$2:$S$91,"polisemico_interno")
A12: lunfardo_sin_homonimo | B12: =COUNTIF('Anotación'!$S$2:$S$91,"lunfardo_sin_homonimo")
A13: espanol_general | B13: =COUNTIF('Anotación'!$S$2:$S$91,"espanol_general")
